2024-12-02 15:51:29 - INFO - Starting execution from planning phase
2024-12-02 15:51:29 - INFO - Starting Planning Phase
2024-12-02 15:51:29 - ERROR - An unexpected error occurred: Traceback (most recent call last):
  File "C:\Users\raisbecka\vscode\o1_Melvin\main.py", line 530, in main
    await planning_phase(r)
  File "C:\Users\raisbecka\vscode\o1_Melvin\main.py", line 269, in planning_phase
    with console.status(f"[bold cyan]STATUS: Read[/bold cyan]") as status2:
  File "C:\Users\raisbecka\AppData\Roaming\Python\Python39\site-packages\rich\status.py", line 97, in __enter__
    self.start()
  File "C:\Users\raisbecka\AppData\Roaming\Python\Python39\site-packages\rich\status.py", line 87, in start
    self._live.start()
  File "C:\Users\raisbecka\AppData\Roaming\Python\Python39\site-packages\rich\live.py", line 113, in start
    self.console.set_live(self)
  File "C:\Users\raisbecka\AppData\Roaming\Python\Python39\site-packages\rich\console.py", line 835, in set_live
    raise errors.LiveError("Only one live display may be active at once")
rich.errors.LiveError: Only one live display may be active at once

